Workbook

Sheet ucty_utf8
A1: číslo účtu | B1: Popis | C1: Poznámka
A2: SK9681800000007000450038 | B2: Príjmový účtet v Štátnej pokladnici: | C2: =VLOOKUP(A2,List1!B:C,2,0) -> Colný úrad - Vymáhanie pohľadávok v zahraničí
A3: SK4281800000007000552763 | B3: Príjmový účtet v Štátnej pokladnici: | C3: =VLOOKUP(A3,List1!B:C,2,0) -> Colný úrad - Exekučný účet
A4: SK3481800000007000450281 | B4: Príjmový účtet v Štátnej pokladnici: | C4: =VLOOKUP(A4,List1!B:C,2,0) -> Colné a daňové príjmy pobočka Banská Bystrica
A5: SK4981800000007000450302 | B5: Príjmový účtet v Štátnej pokladnici: | C5: =VLOOKUP(A5,List1!B:C,2,0) -> Depozit - colná zábezpeka pobočka Banská Bystrica
A6: SK9681800000007000450329 | B6: Príjmový účtet v Štátnej pokladnici: | C6: =VLOOKUP(A6,List1!B:C,2,0) -> Colné a daňové príjmy pobočka Bratislava
A7: SK7481800000007000450337 | B7: Príjmový účtet v Štátnej pokladnici: | C7: =VLOOKUP(A7,List1!B:C,2,0) -> Depozit - colná zábezpeka pobočka Bratislava
A8: SK3081800000007000450353 | B8: Príjmový účtet v Štátnej pokladnici: | C8: =VLOOKUP(A8,List1!B:C,2,0) -> Colné a daňové príjmy pobočka Michalovce
A9: SK0881800000007000450361 | B9: Príjmový účtet v Štátnej pokladnici: | C9: =VLOOKUP(A9,List1!B:C,2,0) -> Depozit - colná zábezpeka pobočka Michalovce
A10: SK3381800000007000450396 | B10: Príjmový účtet v Štátnej pokladnici: | C10: =VLOOKUP(A10,List1!B:C,2,0) -> Colné a daňové príjmy pobočka Košice
A11: SK7081800000007000450409 | B11: Príjmový účtet v Štátnej pokladnici: | C11: =VLOOKUP(A11,List1!B:C,2,0) -> Depozit - colná zábezpeka pobočka Košice
A12: SK2681800000007000450425 | B12: Príjmový účtet v Štátnej pokladnici: | C12: =VLOOKUP(A12,List1!B:C,2,0) -> Colné a daňové príjmy pobočka Trnava
A13: SK0481800000007000450433 | B13: Príjmový účtet v Štátnej pokladnici: | C13: =VLOOKUP(A13,List1!B:C,2,0) -> Depozit - colná zábezpeka pobočka Trnava
... A107: SK5481800000007000617731 | B107: Príjmový účtet v Štátnej pokladnici: | C107: =VLOOKUP(A107,List1!B:C,2,0) -> účet v Štátnej pokladnici, na ktoré smerujú platby oslobodené od transakčnej dane s účinnosťou od 15.5.2025
A108: SK7681800000007000447197 | B108: účtet podľa § 4 ods. 2 písm. k) zákona | D108: =VLOOKUP(A108,List1!B:C,2,0) -> #N/A
A109: SK2581800000007000536288 | B109: účtet podľa § 4 ods. 2 písm. k) zákona | D109: =VLOOKUP(A109,List1!B:C,2,0) -> #N/A
A110: SK7581800000007000536261 | B110: účtet podľa § 4 ods. 2 písm. k) zákona | D110: =VLOOKUP(A110,List1!B:C,2,0) -> #N/A
A111: SK9781800000007000536253 | B111: účtet podľa § 4 ods. 2 písm. k) zákona | D111: =VLOOKUP(A111,List1!B:C,2,0) -> #N/A
A112: SK2281800000007000536245 | B112: účtet podľa § 4 ods. 2 písm. k) zákona | D112: =VLOOKUP(A112,List1!B:C,2,0) -> #N/A
A113: SK3981800000007000538267 | B113: účtet podľa § 4 ods. 2 písm. k) zákona | D113: =VLOOKUP(A113,List1!B:C,2,0) -> #N/A
A114: SK1781800000007000538275 | B114: účtet podľa § 4 ods. 2 písm. k) zákona | C114: =VLOOKUP(A114,List1!B:C,2,0) -> Účet pre odvody na základe rozhodnutí Úradu vládneho auditu (ÚVA) a účtov certifikačného orgánu pre nezrovnalosti a vratky. Platobná jednotka - Ministerstvo hospodárstva. Účet pre ÚVA BA
A115: SK9281800000007000538283 | B115: účtet podľa § 4 ods. 2 písm. k) zákona | C115: =VLOOKUP(A115,List1!B:C,2,0) -> Účet pre odvody na základe rozhodnutí Úradu vládneho auditu (ÚVA) a účtov certifikačného orgánu pre nezrovnalosti a vratky. Platobná jednotka - Ministerstvo hospodárstva. Účet pre ÚVA ZV
A116: SK1081800000007000538304 | B116: účtet podľa § 4 ods. 2 písm. k) zákona | C116: =VLOOKUP(A116,List1!B:C,2,0) -> Účet pre odvody na základe rozhodnutí Úradu vládneho auditu (ÚVA) a účtov certifikačného orgánu pre nezrovnalosti a vratky. Platobná jednotka - Ministerstvo hospodárstva. Účet pre ÚVA KE
A117: SK8581800000007000538312 | B117: účtet podľa § 4 ods. 2 písm. k) zákona | D117: =VLOOKUP(A117,List1!B:C,2,0) -> #N/A
A118: SK5781800000007000678884 | B118: účtet podľa § 4 ods. 2 písm. k) zákona | D118: =VLOOKUP(A118,List1!B:C,2,0) -> #N/A
A119: SK3581800000007000678892 | B119: účtet podľa § 4 ods. 2 písm. k) zákona | D119: =VLOOKUP(A119,List1!B:C,2,0) -> #N/A
A120: SK7681800000007000679027 | B120: účtet podľa § 4 ods. 2 písm. k) zákona | D120: =VLOOKUP(A120,List1!B:C,2,0) -> #N/A
A121: SK3181800000007000693320 | B121: účtet podľa § 4 ods. 2 písm. k) zákona | D121: =VLOOKUP(A121,List1!B:C,2,0) -> #N/A
A122: SK6481800000007000584765 | B122: účtet podľa § 4 ods. 2 písm. k) zákona | D122: =VLOOKUP(A122,List1!B:C,2,0) -> #N/A
A123: SK0681800000007000687465 | B123: účtet podľa § 4 ods. 2 písm. k) zákona | D123: =VLOOKUP(A123,List1!B:C,2,0) -> #N/A
A124: SK8981800000007000539307 | B124: účtet podľa § 4 ods. 2 písm. k) zákona | D124: =VLOOKUP(A124,List1!B:C,2,0) -> #N/A
A125: SK6781800000007000539315 | B125: účtet podľa § 4 ods. 2 písm. k) zákona | C125: =VLOOKUP(A125,List1!B:C,2,0) -> Účet pre odvody na základe rozhodnutí Úradu vládneho auditu (ÚVA) a účtov certifikačného orgánu pre nezrovnalosti a vratky. Platobná jednotka - Ministerstvo vnútra. Účet pre ÚVA BA
A126: SK4581800000007000539323 | B126: účtet podľa § 4 ods. 2 písm. k) zákona | C126: =VLOOKUP(A126,List1!B:C,2,0) -> Účet pre odvody na základe rozhodnutí Úradu vládneho auditu (ÚVA) a účtov certifikačného orgánu pre nezrovnalosti a vratky. Platobná jednotka - Ministerstvo vnútra. Účet pre ÚVA ZV
A127: SK2381800000007000539331 | B127: účtet podľa § 4 ods. 2 písm. k) zákona | C127: =VLOOKUP(A127,List1!B:C,2,0) -> Účet pre odvody na základe rozhodnutí Úradu vládneho auditu (ÚVA) a účtov certifikačného orgánu pre nezrovnalosti a vratky. Platobná jednotka - Ministerstvo vnútra. Účet pre ÚVA KE
A128: SK6181800000007000523030 | B128: účtet podľa § 4 ods. 2 písm. k) zákona | D128: =VLOOKUP(A128,List1!B:C,2,0) -> #N/A
A129: SK2681800000007000678569 | B129: účtet podľa § 4 ods. 2 písm. k) zákona | D129: =VLOOKUP(A129,List1!B:C,2,0) -> #N/A
A130: SK2381800000007000678526 | B130: účtet podľa § 4 ods. 2 písm. k) zákona | D130: =VLOOKUP(A130,List1!B:C,2,0) -> #N/A
A131: SK3081800000007000678497 | B131: účtet podľa § 4 ods. 2 písm. k) zákona | D131: =VLOOKUP(A131,List1!B:C,2,0) -> #N/A
A132: SK1281800000007000661943 | B132: účtet podľa § 4 ods. 2 písm. k) zákona | D132: =VLOOKUP(A132,List1!B:C,2,0) -> #N/A
A133: SK4381800000007000535867 | B133: účtet podľa § 4 ods. 2 písm. k) zákona | D133: =VLOOKUP(A133,List1!B:C,2,0) -> #N/A
...

Sheet List1
B1: Dane z príjmov
B2: Predčíslie príjmového účtu v Štátnej pokladnici | C2: Účel
B3: 500208 | C3: Predčíslie príjmového účtu v Štátnej pokladnici - Daň z príjmu fyzickej osoby - rezident
B4: 500216 | C4: Predčíslie príjmového účtu v Štátnej pokladnici - Daň z príjmu fyzickej osoby - nerezident
B5: 500224 | C5: Predčíslie príjmového účtu v Štátnej pokladnici - Daň z príjmov právnickej osoby so sídlom v tuzemsku
B6: 500232 | C6: Predčíslie príjmového účtu v Štátnej pokladnici - Daň z príjmov právnickej osoby so sídlom v zahraničí
B7: 500259 | C7: Predčíslie príjmového účtu v Štátnej pokladnici - Daň z príjmov fyzických osôb zo závislej činnosti
B8: 500267 | C8: Predčíslie príjmového účtu v Štátnej pokladnici - Daň z príjmov vyberaná zrážkou
B9: 501120 | C9: Predčíslie príjmového účtu v Štátnej pokladnici - Zabezpečenie dane na DPFO
B10: 501139 | C10: Predčíslie príjmového účtu v Štátnej pokladnici - Zabezpečenie dane na DPPO
B12: Spotrebné dane (SPD)
B13: Predčíslie príjmového účtu v Štátnej pokladnici | C13: Účel
B14: 500005 | C14: Predčíslie príjmového účtu v Štátnej pokladnici - SPD z elektriny tuzemsko C
B15: 500013 | C15: Predčíslie príjmového účtu v Štátnej pokladnici - SPD z minerálnych olejov – tuzemsko C
B16: 500021 | C16: Predčíslie príjmového účtu v Štátnej pokladnici - SPD z liehu – tuzemsko C
B17: 500048 | C17: Predčíslie príjmového účtu v Štátnej pokladnici - SPD z piva – tuzemsko C
B18: 500056 | C18: Predčíslie príjmového účtu v Štátnej pokladnici - SPD z tabakových výrobkov – tuzemsko C
B19: 500064 | C19: Predčíslie príjmového účtu v Štátnej pokladnici - DSPD z uhlia - tuzemsko C
B20: 500072 | C20: Predčíslie príjmového účtu v Štátnej pokladnici - SPD z vína – tuzemsko C
B21: 500080 | C21: Predčíslie príjmového účtu v Štátnej pokladnici - SPD zo zemného plynu – tuzemsko C
B23: Depozit – daňová zábezpeka na SPD
B24: Predčíslie príjmového účtu v Štátnej pokladnici | C24: Účel
B25: 500101 | C25: Predčíslie príjmového účtu v Štátnej pokladnici - Depozit – daňová zábezpeka všetkých SPD Banská Bystrica
B26: 500128 | C26: Predčíslie príjmového účtu v Štátnej pokladnici - Depozit – daňová zábezpeka všetkých SPD Bratislava
B27: 500136 | C27: Predčíslie príjmového účtu v Štátnej pokladnici - Depozit – daňová zábezpeka všetkých SPD Michalovce
B28: 500144 | C28: Predčíslie príjmového účtu v Štátnej pokladnici - Depozit – daňová zábezpeka všetkých SPD Košice
B29: 500152 | C29: Predčíslie príjmového účtu v Štátnej pokladnici - Depozit – daňová zábezpeka všetkých SPD Trnava
B30: 500160 | C30: Predčíslie príjmového účtu v Štátnej pokladnici - Depozit – daňová zábezpeka všetkých SPD Žilina
B31: 500179 | C31: Predčíslie príjmového účtu v Štátnej pokladnici - Depozit – daňová zábezpeka všetkých SPD Nitra
B32: 500187 | C32: Predčíslie príjmového účtu v Štátnej pokladnici - Depozit – daňová zábezpeka všetkých SPD Prešov
B33: 500195 | C33: Predčíslie príjmového účtu v Štátnej pokladnici - Depozit – daňová zábezpeka všetkých SPD Trenčín
B35: Iné dane
B36: Predčíslie príjmového účtu v Štátnej pokladnici | C36: Účel
B37: 500240 | C37: Predčíslie príjmového účtu v Štátnej pokladnici - Daň z pridanej hodnoty
B38: 500398 | C38: Predčíslie príjmového účtu v Štátnej pokladnici - Daň z pridanej hodnoty z elektronických služieb
B39: 501163 | C39: Predčíslie príjmového účtu v Štátnej pokladnici - Daň z motorových vozidiel
B40: 501403 | C40: Predčíslie príjmového účtu v Štátnej pokladnici - Daň z finančných transakcií
B41: 501390 | C41: Predčíslie príjmového účtu v Štátnej pokladnici - Daň z poistenia
B42: 501219 | C42: Predčíslie príjmového účtu v Štátnej pokladnici - Daň zo sladených nealkoholických nápojov
B43: 501278 | C43: Predčíslie príjmového účtu v Štátnej pokladnici - Zábezpeka na DPH pre všetky CÚ
...
